<?xml version="1.0" ?>
<!-- =================================================================================== -->
<!-- |    This document was autogenerated by xacro from src/jetbot_description/models/urdf/jetbot.urdf | -->
<!-- |    EDITING THIS FILE BY HAND IS NOT RECOMMENDED                                 | -->
<!-- =================================================================================== -->
<robot name="JetBot">
  <gazebo reference="left_wheel">
    <mu1>0.1</mu1>
    <mu2>0.1</mu2>
    <kp>500.0</kp>
    <kd>10.0</kd>
    <minDepth>0.001</minDepth>
    <maxVel>0.5</maxVel>
    <fdir1>1 0 0</fdir1>
  </gazebo>
  <gazebo reference="right_wheel">
    <mu1>0.1</mu1>
    <mu2>0.1</mu2>
    <kp>500.0</kp>
    <kd>10.0</kd>
    <minDepth>0.001</minDepth>
    <maxVel>0.5</maxVel>
    <fdir1>1 0 0</fdir1>
  </gazebo>
  <gazebo>
    <plugin filename="libgazebo_ros_diff_drive.so" name="diff_drive_controller">
      <commandTopic>cmd_vel</commandTopic>
      <odometryTopic>odom</odometryTopic>
      <odometryFrame>odom</odometryFrame>
      <odometrySource>encoder</odometrySource>
      <publishOdomTF>true</publishOdomTF>
      <robotBaseFrame>base_footprint</robotBaseFrame>
      <publishWheelTF>false</publishWheelTF>
      <publishTf>true</publishTf>
      <publishWheelJointState>true</publishWheelJointState>
      <legacyMode>false</legacyMode>
      <updateRate>30</updateRate>
      <left_joint>left_wheel_hinge</left_joint>
      <right_joint>right_wheel_hinge</right_joint>
      <wheel_separation>0.096</wheel_separation>
      <wheel_diameter>0.065</wheel_diameter>
      <wheelAcceleration>1</wheelAcceleration>
      <wheelTorque>1</wheelTorque>
      <rosDebugLevel>na</rosDebugLevel>
    </plugin>
  </gazebo>
  <gazebo reference="camera_link">
    <sensor name="camera" type="camera">
      <always_on>true</always_on>
      <visualize>true</visualize>
      <camera>
        <horizontal_fov>2.79253</horizontal_fov>
        <image>
          <width>1280</width>
          <height>720</height>
          <format>R8G8B8</format>
        </image>
        <clip>
          <near>0.01</near>
          <far>1</far>
        </clip>
        <noise>
          <type>gaussian</type>
          <mean>0.0</mean>
          <stddev>0.01</stddev>
        </noise>
      </camera>
      <plugin filename="libgazebo_ros_camera.so" name="camera_controller">
        <alwaysOn>true</alwaysOn>
        <updateRate>30.0</updateRate>
        <cameraName>camera</cameraName>
        <frameName>camera_link</frameName>
        <imageTopicName>rgb/image_raw</imageTopicName>
        <cameraInfoTopicName>rgb/camera_info</cameraInfoTopicName>
        <hackBaseline>0.07</hackBaseline>
        <distortionK1>0.0</distortionK1>
        <distortionK2>0.0</distortionK2>
        <distortionK3>0.0</distortionK3>
        <distortionT1>0.0</distortionT1>
        <distortionT2>0.0</distortionT2>
      </plugin>
    </sensor>
  </gazebo>
  <link name="base_footprint"/>
  <joint name="base_joint" type="fixed">
    <parent link="base_footprint"/>
    <child link="base_link"/>
    <origin rpy="0 0 0" xyz="0.0 0.0 0.010"/>
  </joint>
  <joint name="left_wheel_hinge" type="continuous">
    <parent link="base_link"/>
    <child link="left_wheel"/>
    <origin rpy="0       0       1.57079" xyz="0.03     0.05125  0.03"/>
    <axis xyz="1  0  0"/>
  </joint>
  <transmission name="tran_jetbot_left_wheel_hinge">
    <type>transmission_interface/SimpleTransmission</type>
    <joint name="left_wheel_hinge">
      <hardwareInterface>hardware_interface/VelocityJointInterface</hardwareInterface>
    </joint>
    <actuator name="motor_left_wheel">
      <mechanicalReduction>1</mechanicalReduction>
      <hardwareInterface>VelocityJointInterface</hardwareInterface>
    </actuator>
  </transmission>
  <joint name="right_wheel_hinge" type="continuous">
    <parent link="base_link"/>
    <child link="right_wheel"/>
    <origin rpy="0       0       1.57079" xyz="0.03   -0.0595  0.03"/>
    <axis xyz="1  0  0"/>
  </joint>
  <transmission name="tran_jetbot_right_wheel_hinge">
    <type>transmission_interface/SimpleTransmission</type>
    <joint name="right_wheel_hinge">
      <hardwareInterface>hardware_interface/VelocityJointInterface</hardwareInterface>
    </joint>
    <actuator name="motor_right_wheel">
      <mechanicalReduction>1</mechanicalReduction>
    </actuator>
  </transmission>
  <joint name="camera_joint" type="fixed">
    <parent link="base_link"/>
    <child link="camera_link"/>
    <origin rpy="0    0.25  0" xyz="0.065   0      0.0857"/>
    <axis xyz="0.96891  0       0.2474"/>
  </joint>
  <link name="base_link">
    <inertial>
      <mass value="1.0"/>
      <origin rpy="0  0  0" xyz="0  0  0"/>
      <inertia ixx="1e-3" ixy="0" ixz="0" iyy="1e-3" iyz="0" izz="1e-3"/>
    </inertial>
    <collision name="collision">
      <origin rpy="1.57079  0       1.57079" xyz="0     0     0.043"/>
      <geometry>
        <mesh filename="package://meshes/JetBot-v3-Chassis.dae" scale="0.001 0.001 0.001"/>
      </geometry>
    </collision>
    <visual name="visual">
      <origin rpy="1.57079  0       1.57079" xyz="0     0     0.043"/>
      <geometry>
        <mesh filename="package://meshes/JetBot-v3-Chassis.dae" scale="0.001 0.001 0.001"/>
      </geometry>
    </visual>
  </link>
  <link name="left_wheel">
    <inertial>
      <mass value="0.1"/>
      <origin rpy="0  0  0" xyz="0  0  0"/>
      <inertia ixx="1e-3" ixy="0" ixz="0" iyy="1e-3" iyz="0" izz="1e-3"/>
    </inertial>
    <collision name="collision">
      <origin rpy="0  1.570796327 0" xyz="0 0 0"/>
      <geometry>
        <cylinder length="0.008" radius="0.030"/>
      </geometry>
    </collision>
    <visual name="visual">
      <origin rpy="0  0  0" xyz="0  0  0"/>
      <geometry>
        <mesh filename="package://meshes/JetBot-v3-Wheel.stl" scale="0.001 0.001 0.001"/>
      </geometry>
    </visual>
  </link>
  <link name="right_wheel">
    <inertial>
      <mass value="0.1"/>
      <origin rpy="0  0  0" xyz="0  0  0"/>
      <inertia ixx="1e-3" ixy="0" ixz="0" iyy="1e-3" iyz="0" izz="1e-3"/>
    </inertial>
    <collision name="collision">
      <origin rpy="0  1.570796327 0" xyz="0 0 0"/>
      <geometry>
        <cylinder length="0.008" radius="0.030"/>
      </geometry>
    </collision>
    <visual name="visual">
      <origin rpy="0  0  0" xyz="0  0  0"/>
      <geometry>
        <mesh filename="package://meshes/JetBot-v3-Wheel.stl" scale="0.001 0.001 0.001"/>
      </geometry>
    </visual>
  </link>
  <link name="camera_link">
    <inertial>
      <mass value="0.01"/>
      <origin rpy="0  0  0" xyz="0  0  0"/>
      <inertia ixx="0" ixy="0" ixz="0" iyy="0" iyz="0" izz="0"/>
    </inertial>
    <visual name="visual">
      <origin rpy="0  0  0" xyz="0  0  0"/>
      <geometry>
        <box size="0.001 0.001 0.001"/>
      </geometry>
    </visual>
  </link>
</robot>
